<?xml version="1.0"?>
<robot name="roombot" xmlns:xacro="http://ros.org/wiki/xacro">
  <material name="gray">
    <color rgba="0.5 0.5 0.5 2.5"/>
  </material>
  <material name="red">
    <color rgba="1.0 0.0 0.0 2.5"/>
  </material>
  <material name="dark_gray">
    <color rgba="0.2 0.2 0.2 2.5"/>
  </material>

  <xacro:macro name="wheel_macro" params="parent prefix xyz">
    <joint name="${prefix}_joint" type="continuous">
      <origin xyz="${xyz}" rpy="${radians(-90)} 0 0"/>
      <parent link="${parent}"/>
      <child  link="${prefix}_link"/>
      <axis xyz="0 0 1" />
    </joint>
    <link name="${prefix}_link">
      <visual>
        <geometry>
          <cylinder radius="0.033" length="0.007" />
        </geometry>
        <material name="red"/>
      </visual>
    </link>
  </xacro:macro> 

  <link name="odom"/>

  <link name="base_link"/>
  <joint name="base_joint" type="floating">
    <parent link="odom"/>
    <child  link="base_link"/>
  </joint>

  <joint name="body_joint_up" type="fixed">
    <parent link="base_link"/>
    <child  link="body_link_up"/>
    <origin xyz="0 0 0.047" rpy="0 0 0"/>
  </joint>
  <link name="body_link_up">
    <visual>
      <origin xyz="0 0 0" rpy="0 0 0" />
      <geometry>
        <box size="0.145 0.14 0.005" />
      </geometry>
      <material name="gray" />
    </visual>
  </link>

  <joint name="body_joint_down" type="fixed">
    <parent link="base_link"/>
    <child  link="body_link_down"/>
    <origin xyz="0.015 0 0.02" rpy="0 0 0"/>
  </joint>
  <link name="body_link_down">
    <visual>
      <origin xyz="0 0 0" rpy="0 0 0" />
      <geometry>
        <box size="0.115 0.14 0.005" />
      </geometry>
      <material name="gray" />
    </visual>
  </link>

  <xacro:wheel_macro prefix="left_wheel"  parent="base_link" xyz="0.035 0.0825 0.033"/>
  <xacro:wheel_macro prefix="right_wheel" parent="base_link" xyz="0.035 -0.0825 0.033"/>

  <joint name="ball_joint" type="fixed">
    <parent link="base_link"/>
    <child  link="ball_link"/>
    <origin xyz="-0.065 0 0.01" rpy="0 0 0"/>
  </joint>
  <link name="ball_link">
   <visual>
     <origin xyz="0 0 0" rpy="0 0 0" />
     <geometry>
       <sphere radius="0.01" />
     </geometry>
     <material name="gray" />
   </visual>
  </link>

  <joint name="zed_joint" type="fixed">
    <parent link="body_link_up" />
    <child link="zed_link" />
    <origin xyz="0.068 -0.01 0.017 " rpy="0 0 0" />
  </joint>
  <link name="zed_link">
    <visual>
      <geometry>
        <mesh filename="package://zed_wrapper/urdf/models/ZEDM.stl" />
      </geometry>
      <origin xyz="0 0 0 " rpy="0 0 0" />
      <material name="dark_gray" />
    </visual>
  </link>

  <joint name="rplidar_joint" type="fixed">
    <parent link="body_link_up" />
    <child link="rplidar_link" />
    <origin xyz="0.02 0.01 0.04 " rpy="0 0 1.5707963267949" />
  </joint>
  <link name="rplidar_link">
    <visual>
      <geometry>
        <mesh filename="package://motor_node/stl/rplidar-a1m8.stl" />
      </geometry>
      <origin xyz="0 0 0 " rpy="0 0 0" />
      <material name="dark_gray" />
    </visual>
  </link>

  <joint name="jetson_joint" type="fixed">
    <parent link="body_link_up" />
    <child link="jetson_link" />
    <origin xyz="-0.045 0.00 0.02 " rpy="0 0 0" />
  </joint>
  <link name="jetson_link">
    <visual>
      <geometry>
        <mesh filename="package://motor_node/stl/jetson.stl" />
      </geometry>
      <origin xyz="0 0 0 " rpy="0 0 0" />
      <material name="gray" />
    </visual>
  </link>

</robot>
